[2022-07-25 13:06:55,277] {taskinstance.py:1179} INFO - Dependencies all met for <TaskInstance: final_dag_test.process_data scheduled__2022-07-21T00:00:00+00:00 [queued]>
[2022-07-25 13:06:55,308] {taskinstance.py:1179} INFO - Dependencies all met for <TaskInstance: final_dag_test.process_data scheduled__2022-07-21T00:00:00+00:00 [queued]>
[2022-07-25 13:06:55,310] {taskinstance.py:1376} INFO - 
--------------------------------------------------------------------------------
[2022-07-25 13:06:55,311] {taskinstance.py:1377} INFO - Starting attempt 1 of 2
[2022-07-25 13:06:55,312] {taskinstance.py:1378} INFO - 
--------------------------------------------------------------------------------
[2022-07-25 13:06:55,371] {taskinstance.py:1397} INFO - Executing <Task(PythonOperator): process_data> on 2022-07-21 00:00:00+00:00
[2022-07-25 13:06:55,402] {standard_task_runner.py:52} INFO - Started process 2856 to run task
[2022-07-25 13:06:55,438] {standard_task_runner.py:79} INFO - Running: ['***', 'tasks', 'run', 'final_dag_test', 'process_data', 'scheduled__2022-07-21T00:00:00+00:00', '--job-id', '378', '--raw', '--subdir', 'DAGS_FOLDER/final_dag.py', '--cfg-path', '/tmp/tmpg8lsmrlk', '--error-file', '/tmp/tmp3ctb2_jy']
[2022-07-25 13:06:55,447] {standard_task_runner.py:80} INFO - Job 378: Subtask process_data
[2022-07-25 13:06:55,512] {logging_mixin.py:115} WARNING - /home/***/.local/lib/python3.7/site-packages/***/configuration.py:528 DeprecationWarning: The sql_alchemy_conn option in [core] has been moved to the sql_alchemy_conn option in [database] - the old setting has been used, but please update your config.
[2022-07-25 13:06:55,675] {task_command.py:371} INFO - Running <TaskInstance: final_dag_test.process_data scheduled__2022-07-21T00:00:00+00:00 [running]> on host 929e6a3728d4
[2022-07-25 13:06:55,892] {taskinstance.py:1591} INFO - Exporting the following env vars:
AIRFLOW_CTX_DAG_EMAIL=caroline.kosalka@gmail.com
AIRFLOW_CTX_DAG_OWNER=***
AIRFLOW_CTX_DAG_ID=final_dag_test
AIRFLOW_CTX_TASK_ID=process_data
AIRFLOW_CTX_EXECUTION_DATE=2022-07-21T00:00:00+00:00
AIRFLOW_CTX_TRY_NUMBER=1
AIRFLOW_CTX_DAG_RUN_ID=scheduled__2022-07-21T00:00:00+00:00
[2022-07-25 13:06:55,933] {taskinstance.py:1909} ERROR - Task failed with exception
Traceback (most recent call last):
  File "/home/airflow/.local/lib/python3.7/site-packages/airflow/operators/python.py", line 171, in execute
    return_value = self.execute_callable()
  File "/home/airflow/.local/lib/python3.7/site-packages/airflow/operators/python.py", line 189, in execute_callable
    return self.python_callable(*self.op_args, **self.op_kwargs)
  File "/opt/airflow/dags/final_dag.py", line 23, in process_terminal_data
    raise Exception('No data.')
Exception: No data.
[2022-07-25 13:06:55,961] {taskinstance.py:1420} INFO - Marking task as UP_FOR_RETRY. dag_id=final_dag_test, task_id=process_data, execution_date=20220721T000000, start_date=20220725T130655, end_date=20220725T130655
[2022-07-25 13:06:56,008] {standard_task_runner.py:97} ERROR - Failed to execute job 378 for task process_data (No data.; 2856)
[2022-07-25 13:06:56,037] {local_task_job.py:156} INFO - Task exited with return code 1
[2022-07-25 13:06:56,200] {local_task_job.py:273} INFO - 0 downstream tasks scheduled from follow-on schedule check
