[2022-07-25 12:50:42,306] {taskinstance.py:1179} INFO - Dependencies all met for <TaskInstance: final_dag_test.process_data scheduled__2022-06-01T00:00:00+00:00 [queued]>
[2022-07-25 12:50:42,433] {taskinstance.py:1179} INFO - Dependencies all met for <TaskInstance: final_dag_test.process_data scheduled__2022-06-01T00:00:00+00:00 [queued]>
[2022-07-25 12:50:42,434] {taskinstance.py:1376} INFO - 
--------------------------------------------------------------------------------
[2022-07-25 12:50:42,434] {taskinstance.py:1377} INFO - Starting attempt 1 of 2
[2022-07-25 12:50:42,436] {taskinstance.py:1378} INFO - 
--------------------------------------------------------------------------------
[2022-07-25 12:50:42,555] {taskinstance.py:1397} INFO - Executing <Task(PythonOperator): process_data> on 2022-06-01 00:00:00+00:00
[2022-07-25 12:50:42,657] {standard_task_runner.py:52} INFO - Started process 1787 to run task
[2022-07-25 12:50:42,743] {standard_task_runner.py:79} INFO - Running: ['***', 'tasks', 'run', 'final_dag_test', 'process_data', 'scheduled__2022-06-01T00:00:00+00:00', '--job-id', '185', '--raw', '--subdir', 'DAGS_FOLDER/final_dag.py', '--cfg-path', '/tmp/tmpy9nx29gm', '--error-file', '/tmp/tmpau24p4i6']
[2022-07-25 12:50:42,764] {standard_task_runner.py:80} INFO - Job 185: Subtask process_data
[2022-07-25 12:50:43,086] {logging_mixin.py:115} WARNING - /home/***/.local/lib/python3.7/site-packages/***/configuration.py:528 DeprecationWarning: The sql_alchemy_conn option in [core] has been moved to the sql_alchemy_conn option in [database] - the old setting has been used, but please update your config.
[2022-07-25 12:50:43,629] {task_command.py:371} INFO - Running <TaskInstance: final_dag_test.process_data scheduled__2022-06-01T00:00:00+00:00 [running]> on host 929e6a3728d4
[2022-07-25 12:50:44,237] {taskinstance.py:1591} INFO - Exporting the following env vars:
AIRFLOW_CTX_DAG_EMAIL=caroline.kosalka@gmail.com
AIRFLOW_CTX_DAG_OWNER=***
AIRFLOW_CTX_DAG_ID=final_dag_test
AIRFLOW_CTX_TASK_ID=process_data
AIRFLOW_CTX_EXECUTION_DATE=2022-06-01T00:00:00+00:00
AIRFLOW_CTX_TRY_NUMBER=1
AIRFLOW_CTX_DAG_RUN_ID=scheduled__2022-06-01T00:00:00+00:00
[2022-07-25 12:50:44,390] {taskinstance.py:1909} ERROR - Task failed with exception
Traceback (most recent call last):
  File "/home/airflow/.local/lib/python3.7/site-packages/airflow/operators/python.py", line 171, in execute
    return_value = self.execute_callable()
  File "/home/airflow/.local/lib/python3.7/site-packages/airflow/operators/python.py", line 189, in execute_callable
    return self.python_callable(*self.op_args, **self.op_kwargs)
  File "/opt/airflow/dags/final_dag.py", line 23, in process_terminal_data
    raise Exception('No data.')
Exception: No data.
[2022-07-25 12:50:44,562] {taskinstance.py:1420} INFO - Marking task as UP_FOR_RETRY. dag_id=final_dag_test, task_id=process_data, execution_date=20220601T000000, start_date=20220725T125042, end_date=20220725T125044
[2022-07-25 12:50:44,783] {standard_task_runner.py:97} ERROR - Failed to execute job 185 for task process_data (No data.; 1787)
[2022-07-25 12:50:44,947] {local_task_job.py:156} INFO - Task exited with return code 1
[2022-07-25 12:50:45,599] {local_task_job.py:273} INFO - 0 downstream tasks scheduled from follow-on schedule check
