[2022-07-25 12:50:45,547] {taskinstance.py:1179} INFO - Dependencies all met for <TaskInstance: final_dag_test.process_data scheduled__2022-06-07T00:00:00+00:00 [queued]>
[2022-07-25 12:50:45,676] {taskinstance.py:1179} INFO - Dependencies all met for <TaskInstance: final_dag_test.process_data scheduled__2022-06-07T00:00:00+00:00 [queued]>
[2022-07-25 12:50:45,683] {taskinstance.py:1376} INFO - 
--------------------------------------------------------------------------------
[2022-07-25 12:50:45,685] {taskinstance.py:1377} INFO - Starting attempt 1 of 2
[2022-07-25 12:50:45,688] {taskinstance.py:1378} INFO - 
--------------------------------------------------------------------------------
[2022-07-25 12:50:45,806] {taskinstance.py:1397} INFO - Executing <Task(PythonOperator): process_data> on 2022-06-07 00:00:00+00:00
[2022-07-25 12:50:45,823] {standard_task_runner.py:52} INFO - Started process 1803 to run task
[2022-07-25 12:50:46,034] {standard_task_runner.py:79} INFO - Running: ['***', 'tasks', 'run', 'final_dag_test', 'process_data', 'scheduled__2022-06-07T00:00:00+00:00', '--job-id', '193', '--raw', '--subdir', 'DAGS_FOLDER/final_dag.py', '--cfg-path', '/tmp/tmpb4amtsdo', '--error-file', '/tmp/tmp3rl8bm9l']
[2022-07-25 12:50:46,056] {standard_task_runner.py:80} INFO - Job 193: Subtask process_data
[2022-07-25 12:50:46,304] {logging_mixin.py:115} WARNING - /home/***/.local/lib/python3.7/site-packages/***/configuration.py:528 DeprecationWarning: The sql_alchemy_conn option in [core] has been moved to the sql_alchemy_conn option in [database] - the old setting has been used, but please update your config.
[2022-07-25 12:50:47,063] {task_command.py:371} INFO - Running <TaskInstance: final_dag_test.process_data scheduled__2022-06-07T00:00:00+00:00 [running]> on host 929e6a3728d4
[2022-07-25 12:50:47,555] {taskinstance.py:1591} INFO - Exporting the following env vars:
AIRFLOW_CTX_DAG_EMAIL=caroline.kosalka@gmail.com
AIRFLOW_CTX_DAG_OWNER=***
AIRFLOW_CTX_DAG_ID=final_dag_test
AIRFLOW_CTX_TASK_ID=process_data
AIRFLOW_CTX_EXECUTION_DATE=2022-06-07T00:00:00+00:00
AIRFLOW_CTX_TRY_NUMBER=1
AIRFLOW_CTX_DAG_RUN_ID=scheduled__2022-06-07T00:00:00+00:00
[2022-07-25 12:50:47,687] {taskinstance.py:1909} ERROR - Task failed with exception
Traceback (most recent call last):
  File "/home/airflow/.local/lib/python3.7/site-packages/airflow/operators/python.py", line 171, in execute
    return_value = self.execute_callable()
  File "/home/airflow/.local/lib/python3.7/site-packages/airflow/operators/python.py", line 189, in execute_callable
    return self.python_callable(*self.op_args, **self.op_kwargs)
  File "/opt/airflow/dags/final_dag.py", line 23, in process_terminal_data
    raise Exception('No data.')
Exception: No data.
[2022-07-25 12:50:47,761] {taskinstance.py:1420} INFO - Marking task as UP_FOR_RETRY. dag_id=final_dag_test, task_id=process_data, execution_date=20220607T000000, start_date=20220725T125045, end_date=20220725T125047
[2022-07-25 12:50:48,407] {standard_task_runner.py:97} ERROR - Failed to execute job 193 for task process_data (No data.; 1803)
[2022-07-25 12:50:48,520] {local_task_job.py:156} INFO - Task exited with return code 1
[2022-07-25 12:50:48,760] {local_task_job.py:273} INFO - 0 downstream tasks scheduled from follow-on schedule check
