[2022-07-25 13:01:31,397] {taskinstance.py:1179} INFO - Dependencies all met for <TaskInstance: final_dag_test.process_data scheduled__2022-07-06T00:00:00+00:00 [queued]>
[2022-07-25 13:01:31,480] {taskinstance.py:1179} INFO - Dependencies all met for <TaskInstance: final_dag_test.process_data scheduled__2022-07-06T00:00:00+00:00 [queued]>
[2022-07-25 13:01:31,512] {taskinstance.py:1376} INFO - 
--------------------------------------------------------------------------------
[2022-07-25 13:01:31,524] {taskinstance.py:1377} INFO - Starting attempt 1 of 2
[2022-07-25 13:01:31,535] {taskinstance.py:1378} INFO - 
--------------------------------------------------------------------------------
[2022-07-25 13:01:31,620] {taskinstance.py:1397} INFO - Executing <Task(PythonOperator): process_data> on 2022-07-06 00:00:00+00:00
[2022-07-25 13:01:31,649] {standard_task_runner.py:52} INFO - Started process 2509 to run task
[2022-07-25 13:01:31,676] {standard_task_runner.py:79} INFO - Running: ['***', 'tasks', 'run', 'final_dag_test', 'process_data', 'scheduled__2022-07-06T00:00:00+00:00', '--job-id', '315', '--raw', '--subdir', 'DAGS_FOLDER/final_dag.py', '--cfg-path', '/tmp/tmp2rvxesgc', '--error-file', '/tmp/tmpbpic8vqw']
[2022-07-25 13:01:31,682] {standard_task_runner.py:80} INFO - Job 315: Subtask process_data
[2022-07-25 13:01:31,751] {logging_mixin.py:115} WARNING - /home/***/.local/lib/python3.7/site-packages/***/configuration.py:528 DeprecationWarning: The sql_alchemy_conn option in [core] has been moved to the sql_alchemy_conn option in [database] - the old setting has been used, but please update your config.
[2022-07-25 13:01:31,985] {task_command.py:371} INFO - Running <TaskInstance: final_dag_test.process_data scheduled__2022-07-06T00:00:00+00:00 [running]> on host 929e6a3728d4
[2022-07-25 13:01:32,357] {taskinstance.py:1591} INFO - Exporting the following env vars:
AIRFLOW_CTX_DAG_EMAIL=caroline.kosalka@gmail.com
AIRFLOW_CTX_DAG_OWNER=***
AIRFLOW_CTX_DAG_ID=final_dag_test
AIRFLOW_CTX_TASK_ID=process_data
AIRFLOW_CTX_EXECUTION_DATE=2022-07-06T00:00:00+00:00
AIRFLOW_CTX_TRY_NUMBER=1
AIRFLOW_CTX_DAG_RUN_ID=scheduled__2022-07-06T00:00:00+00:00
[2022-07-25 13:01:32,398] {taskinstance.py:1909} ERROR - Task failed with exception
Traceback (most recent call last):
  File "/home/airflow/.local/lib/python3.7/site-packages/airflow/operators/python.py", line 171, in execute
    return_value = self.execute_callable()
  File "/home/airflow/.local/lib/python3.7/site-packages/airflow/operators/python.py", line 189, in execute_callable
    return self.python_callable(*self.op_args, **self.op_kwargs)
  File "/opt/airflow/dags/final_dag.py", line 23, in process_terminal_data
    raise Exception('No data.')
Exception: No data.
[2022-07-25 13:01:32,471] {taskinstance.py:1420} INFO - Marking task as UP_FOR_RETRY. dag_id=final_dag_test, task_id=process_data, execution_date=20220706T000000, start_date=20220725T130131, end_date=20220725T130132
[2022-07-25 13:01:32,542] {standard_task_runner.py:97} ERROR - Failed to execute job 315 for task process_data (No data.; 2509)
[2022-07-25 13:01:32,602] {local_task_job.py:156} INFO - Task exited with return code 1
[2022-07-25 13:01:32,807] {local_task_job.py:273} INFO - 0 downstream tasks scheduled from follow-on schedule check
