[2022-07-25 12:56:09,965] {taskinstance.py:1179} INFO - Dependencies all met for <TaskInstance: final_dag_test.process_data scheduled__2022-06-19T00:00:00+00:00 [queued]>
[2022-07-25 12:56:10,044] {taskinstance.py:1179} INFO - Dependencies all met for <TaskInstance: final_dag_test.process_data scheduled__2022-06-19T00:00:00+00:00 [queued]>
[2022-07-25 12:56:10,051] {taskinstance.py:1376} INFO - 
--------------------------------------------------------------------------------
[2022-07-25 12:56:10,052] {taskinstance.py:1377} INFO - Starting attempt 1 of 2
[2022-07-25 12:56:10,053] {taskinstance.py:1378} INFO - 
--------------------------------------------------------------------------------
[2022-07-25 12:56:10,122] {taskinstance.py:1397} INFO - Executing <Task(PythonOperator): process_data> on 2022-06-19 00:00:00+00:00
[2022-07-25 12:56:10,169] {standard_task_runner.py:52} INFO - Started process 2150 to run task
[2022-07-25 12:56:10,188] {standard_task_runner.py:79} INFO - Running: ['***', 'tasks', 'run', 'final_dag_test', 'process_data', 'scheduled__2022-06-19T00:00:00+00:00', '--job-id', '251', '--raw', '--subdir', 'DAGS_FOLDER/final_dag.py', '--cfg-path', '/tmp/tmpysz61r59', '--error-file', '/tmp/tmpfhkyjp1m']
[2022-07-25 12:56:10,213] {standard_task_runner.py:80} INFO - Job 251: Subtask process_data
[2022-07-25 12:56:10,504] {logging_mixin.py:115} WARNING - /home/***/.local/lib/python3.7/site-packages/***/configuration.py:528 DeprecationWarning: The sql_alchemy_conn option in [core] has been moved to the sql_alchemy_conn option in [database] - the old setting has been used, but please update your config.
[2022-07-25 12:56:11,005] {task_command.py:371} INFO - Running <TaskInstance: final_dag_test.process_data scheduled__2022-06-19T00:00:00+00:00 [running]> on host 929e6a3728d4
[2022-07-25 12:56:11,618] {taskinstance.py:1591} INFO - Exporting the following env vars:
AIRFLOW_CTX_DAG_EMAIL=caroline.kosalka@gmail.com
AIRFLOW_CTX_DAG_OWNER=***
AIRFLOW_CTX_DAG_ID=final_dag_test
AIRFLOW_CTX_TASK_ID=process_data
AIRFLOW_CTX_EXECUTION_DATE=2022-06-19T00:00:00+00:00
AIRFLOW_CTX_TRY_NUMBER=1
AIRFLOW_CTX_DAG_RUN_ID=scheduled__2022-06-19T00:00:00+00:00
[2022-07-25 12:56:11,742] {taskinstance.py:1909} ERROR - Task failed with exception
Traceback (most recent call last):
  File "/home/airflow/.local/lib/python3.7/site-packages/airflow/operators/python.py", line 171, in execute
    return_value = self.execute_callable()
  File "/home/airflow/.local/lib/python3.7/site-packages/airflow/operators/python.py", line 189, in execute_callable
    return self.python_callable(*self.op_args, **self.op_kwargs)
  File "/opt/airflow/dags/final_dag.py", line 23, in process_terminal_data
    raise Exception('No data.')
Exception: No data.
[2022-07-25 12:56:11,808] {taskinstance.py:1420} INFO - Marking task as UP_FOR_RETRY. dag_id=final_dag_test, task_id=process_data, execution_date=20220619T000000, start_date=20220725T125609, end_date=20220725T125611
[2022-07-25 12:56:11,980] {standard_task_runner.py:97} ERROR - Failed to execute job 251 for task process_data (No data.; 2150)
[2022-07-25 12:56:12,084] {local_task_job.py:156} INFO - Task exited with return code 1
[2022-07-25 12:56:12,530] {local_task_job.py:273} INFO - 0 downstream tasks scheduled from follow-on schedule check
