[2022-07-25 13:01:29,206] {taskinstance.py:1179} INFO - Dependencies all met for <TaskInstance: final_dag_test.process_data scheduled__2022-07-04T00:00:00+00:00 [queued]>
[2022-07-25 13:01:29,242] {taskinstance.py:1179} INFO - Dependencies all met for <TaskInstance: final_dag_test.process_data scheduled__2022-07-04T00:00:00+00:00 [queued]>
[2022-07-25 13:01:29,246] {taskinstance.py:1376} INFO - 
--------------------------------------------------------------------------------
[2022-07-25 13:01:29,248] {taskinstance.py:1377} INFO - Starting attempt 1 of 2
[2022-07-25 13:01:29,249] {taskinstance.py:1378} INFO - 
--------------------------------------------------------------------------------
[2022-07-25 13:01:29,310] {taskinstance.py:1397} INFO - Executing <Task(PythonOperator): process_data> on 2022-07-04 00:00:00+00:00
[2022-07-25 13:01:29,338] {standard_task_runner.py:52} INFO - Started process 2499 to run task
[2022-07-25 13:01:29,369] {standard_task_runner.py:79} INFO - Running: ['***', 'tasks', 'run', 'final_dag_test', 'process_data', 'scheduled__2022-07-04T00:00:00+00:00', '--job-id', '310', '--raw', '--subdir', 'DAGS_FOLDER/final_dag.py', '--cfg-path', '/tmp/tmpco52xtl9', '--error-file', '/tmp/tmpu6ab9e5_']
[2022-07-25 13:01:29,378] {standard_task_runner.py:80} INFO - Job 310: Subtask process_data
[2022-07-25 13:01:29,509] {logging_mixin.py:115} WARNING - /home/***/.local/lib/python3.7/site-packages/***/configuration.py:528 DeprecationWarning: The sql_alchemy_conn option in [core] has been moved to the sql_alchemy_conn option in [database] - the old setting has been used, but please update your config.
[2022-07-25 13:01:29,927] {task_command.py:371} INFO - Running <TaskInstance: final_dag_test.process_data scheduled__2022-07-04T00:00:00+00:00 [running]> on host 929e6a3728d4
[2022-07-25 13:01:30,538] {taskinstance.py:1591} INFO - Exporting the following env vars:
AIRFLOW_CTX_DAG_EMAIL=caroline.kosalka@gmail.com
AIRFLOW_CTX_DAG_OWNER=***
AIRFLOW_CTX_DAG_ID=final_dag_test
AIRFLOW_CTX_TASK_ID=process_data
AIRFLOW_CTX_EXECUTION_DATE=2022-07-04T00:00:00+00:00
AIRFLOW_CTX_TRY_NUMBER=1
AIRFLOW_CTX_DAG_RUN_ID=scheduled__2022-07-04T00:00:00+00:00
[2022-07-25 13:01:30,702] {taskinstance.py:1909} ERROR - Task failed with exception
Traceback (most recent call last):
  File "/home/airflow/.local/lib/python3.7/site-packages/airflow/operators/python.py", line 171, in execute
    return_value = self.execute_callable()
  File "/home/airflow/.local/lib/python3.7/site-packages/airflow/operators/python.py", line 189, in execute_callable
    return self.python_callable(*self.op_args, **self.op_kwargs)
  File "/opt/airflow/dags/final_dag.py", line 23, in process_terminal_data
    raise Exception('No data.')
Exception: No data.
[2022-07-25 13:01:30,745] {taskinstance.py:1420} INFO - Marking task as UP_FOR_RETRY. dag_id=final_dag_test, task_id=process_data, execution_date=20220704T000000, start_date=20220725T130129, end_date=20220725T130130
[2022-07-25 13:01:30,829] {standard_task_runner.py:97} ERROR - Failed to execute job 310 for task process_data (No data.; 2499)
[2022-07-25 13:01:30,928] {local_task_job.py:156} INFO - Task exited with return code 1
[2022-07-25 13:01:31,112] {local_task_job.py:273} INFO - 0 downstream tasks scheduled from follow-on schedule check
