[2022-07-25 12:50:44,857] {taskinstance.py:1179} INFO - Dependencies all met for <TaskInstance: final_dag_test.process_data scheduled__2022-06-06T00:00:00+00:00 [queued]>
[2022-07-25 12:50:45,093] {taskinstance.py:1179} INFO - Dependencies all met for <TaskInstance: final_dag_test.process_data scheduled__2022-06-06T00:00:00+00:00 [queued]>
[2022-07-25 12:50:45,095] {taskinstance.py:1376} INFO - 
--------------------------------------------------------------------------------
[2022-07-25 12:50:45,101] {taskinstance.py:1377} INFO - Starting attempt 1 of 2
[2022-07-25 12:50:45,119] {taskinstance.py:1378} INFO - 
--------------------------------------------------------------------------------
[2022-07-25 12:50:45,316] {taskinstance.py:1397} INFO - Executing <Task(PythonOperator): process_data> on 2022-06-06 00:00:00+00:00
[2022-07-25 12:50:45,334] {standard_task_runner.py:52} INFO - Started process 1798 to run task
[2022-07-25 12:50:45,349] {standard_task_runner.py:79} INFO - Running: ['***', 'tasks', 'run', 'final_dag_test', 'process_data', 'scheduled__2022-06-06T00:00:00+00:00', '--job-id', '190', '--raw', '--subdir', 'DAGS_FOLDER/final_dag.py', '--cfg-path', '/tmp/tmpmgdnxzwb', '--error-file', '/tmp/tmp9k4ljjvg']
[2022-07-25 12:50:45,358] {standard_task_runner.py:80} INFO - Job 190: Subtask process_data
[2022-07-25 12:50:45,442] {logging_mixin.py:115} WARNING - /home/***/.local/lib/python3.7/site-packages/***/configuration.py:528 DeprecationWarning: The sql_alchemy_conn option in [core] has been moved to the sql_alchemy_conn option in [database] - the old setting has been used, but please update your config.
[2022-07-25 12:50:45,856] {task_command.py:371} INFO - Running <TaskInstance: final_dag_test.process_data scheduled__2022-06-06T00:00:00+00:00 [running]> on host 929e6a3728d4
[2022-07-25 12:50:47,175] {taskinstance.py:1591} INFO - Exporting the following env vars:
AIRFLOW_CTX_DAG_EMAIL=caroline.kosalka@gmail.com
AIRFLOW_CTX_DAG_OWNER=***
AIRFLOW_CTX_DAG_ID=final_dag_test
AIRFLOW_CTX_TASK_ID=process_data
AIRFLOW_CTX_EXECUTION_DATE=2022-06-06T00:00:00+00:00
AIRFLOW_CTX_TRY_NUMBER=1
AIRFLOW_CTX_DAG_RUN_ID=scheduled__2022-06-06T00:00:00+00:00
[2022-07-25 12:50:47,261] {taskinstance.py:1909} ERROR - Task failed with exception
Traceback (most recent call last):
  File "/home/airflow/.local/lib/python3.7/site-packages/airflow/operators/python.py", line 171, in execute
    return_value = self.execute_callable()
  File "/home/airflow/.local/lib/python3.7/site-packages/airflow/operators/python.py", line 189, in execute_callable
    return self.python_callable(*self.op_args, **self.op_kwargs)
  File "/opt/airflow/dags/final_dag.py", line 23, in process_terminal_data
    raise Exception('No data.')
Exception: No data.
[2022-07-25 12:50:47,333] {taskinstance.py:1420} INFO - Marking task as UP_FOR_RETRY. dag_id=final_dag_test, task_id=process_data, execution_date=20220606T000000, start_date=20220725T125044, end_date=20220725T125047
[2022-07-25 12:50:47,449] {standard_task_runner.py:97} ERROR - Failed to execute job 190 for task process_data (No data.; 1798)
[2022-07-25 12:50:47,555] {local_task_job.py:156} INFO - Task exited with return code 1
[2022-07-25 12:50:47,785] {local_task_job.py:273} INFO - 0 downstream tasks scheduled from follow-on schedule check
