[2022-07-25 12:55:53,891] {taskinstance.py:1179} INFO - Dependencies all met for <TaskInstance: final_dag_test.process_data scheduled__2022-06-06T00:00:00+00:00 [queued]>
[2022-07-25 12:55:54,081] {taskinstance.py:1179} INFO - Dependencies all met for <TaskInstance: final_dag_test.process_data scheduled__2022-06-06T00:00:00+00:00 [queued]>
[2022-07-25 12:55:54,083] {taskinstance.py:1376} INFO - 
--------------------------------------------------------------------------------
[2022-07-25 12:55:54,085] {taskinstance.py:1377} INFO - Starting attempt 2 of 2
[2022-07-25 12:55:54,087] {taskinstance.py:1378} INFO - 
--------------------------------------------------------------------------------
[2022-07-25 12:55:54,344] {taskinstance.py:1397} INFO - Executing <Task(PythonOperator): process_data> on 2022-06-06 00:00:00+00:00
[2022-07-25 12:55:54,385] {standard_task_runner.py:52} INFO - Started process 2049 to run task
[2022-07-25 12:55:54,402] {standard_task_runner.py:79} INFO - Running: ['***', 'tasks', 'run', 'final_dag_test', 'process_data', 'scheduled__2022-06-06T00:00:00+00:00', '--job-id', '218', '--raw', '--subdir', 'DAGS_FOLDER/final_dag.py', '--cfg-path', '/tmp/tmpc6a2knii', '--error-file', '/tmp/tmpwyga7msa']
[2022-07-25 12:55:54,406] {standard_task_runner.py:80} INFO - Job 218: Subtask process_data
[2022-07-25 12:55:54,508] {logging_mixin.py:115} WARNING - /home/***/.local/lib/python3.7/site-packages/***/configuration.py:528 DeprecationWarning: The sql_alchemy_conn option in [core] has been moved to the sql_alchemy_conn option in [database] - the old setting has been used, but please update your config.
[2022-07-25 12:55:55,127] {task_command.py:371} INFO - Running <TaskInstance: final_dag_test.process_data scheduled__2022-06-06T00:00:00+00:00 [running]> on host 929e6a3728d4
[2022-07-25 12:55:55,977] {taskinstance.py:1591} INFO - Exporting the following env vars:
AIRFLOW_CTX_DAG_EMAIL=caroline.kosalka@gmail.com
AIRFLOW_CTX_DAG_OWNER=***
AIRFLOW_CTX_DAG_ID=final_dag_test
AIRFLOW_CTX_TASK_ID=process_data
AIRFLOW_CTX_EXECUTION_DATE=2022-06-06T00:00:00+00:00
AIRFLOW_CTX_TRY_NUMBER=2
AIRFLOW_CTX_DAG_RUN_ID=scheduled__2022-06-06T00:00:00+00:00
[2022-07-25 12:55:56,012] {taskinstance.py:1909} ERROR - Task failed with exception
Traceback (most recent call last):
  File "/home/airflow/.local/lib/python3.7/site-packages/airflow/operators/python.py", line 171, in execute
    return_value = self.execute_callable()
  File "/home/airflow/.local/lib/python3.7/site-packages/airflow/operators/python.py", line 189, in execute_callable
    return self.python_callable(*self.op_args, **self.op_kwargs)
  File "/opt/airflow/dags/final_dag.py", line 23, in process_terminal_data
    raise Exception('No data.')
Exception: No data.
[2022-07-25 12:55:56,086] {taskinstance.py:1420} INFO - Marking task as FAILED. dag_id=final_dag_test, task_id=process_data, execution_date=20220606T000000, start_date=20220725T125553, end_date=20220725T125556
[2022-07-25 12:55:56,175] {standard_task_runner.py:97} ERROR - Failed to execute job 218 for task process_data (No data.; 2049)
[2022-07-25 12:55:56,247] {local_task_job.py:156} INFO - Task exited with return code 1
[2022-07-25 12:55:56,426] {local_task_job.py:273} INFO - 0 downstream tasks scheduled from follow-on schedule check
